nohup: ignoring input
I tensorflow/stream_executor/dso_loader.cc:128] successfully opened CUDA library libcublas.so.7.5 locally
I tensorflow/stream_executor/dso_loader.cc:128] successfully opened CUDA library libcudnn.so.5 locally
I tensorflow/stream_executor/dso_loader.cc:128] successfully opened CUDA library libcufft.so.7.5 locally
I tensorflow/stream_executor/dso_loader.cc:128] successfully opened CUDA library libcuda.so.1 locally
I tensorflow/stream_executor/dso_loader.cc:128] successfully opened CUDA library libcurand.so.7.5 locally
num of tress 100
node type size: 420
max width of every level: 178
shape of input (1, 36, 178, 2)
train trees (1, 50)
output (1, 10)
which cluster [0, 1, 0, 1, 1, 1, 1, 2, 3, 4, 2, 2, 2, 2, 2, 2, 2, 2, 0, 5, 5, 1, 3, 6, 3, 1, 7, 6, 6, 1, 0, 3, 5, 8, 7, 8, 6, 4, 0, 1, 5, 9, 5, 7, 7, 8, 9, 9, 9, 9, 4, 4, 9, 4, 4, 8, 6, 8, 8, 8, 8, 6, 3, 0, 4, 8, 7, 0, 4, 6, 4, 3, 3, 6, 2, 3, 0, 9, 0, 3, 5, 7, 7, 5, 8, 0, 7, 7, 6, 5, 9, 6, 9, 4, 5, 9, 5, 1, 7, 3]
I tensorflow/core/common_runtime/gpu/gpu_device.cc:885] Found device 0 with properties: 
name: GeForce GTX 970
major: 5 minor: 2 memoryClockRate (GHz) 1.329
pciBusID 0000:03:00.0
Total memory: 4.00GiB
Free memory: 3.90GiB
W tensorflow/stream_executor/cuda/cuda_driver.cc:590] creating context when one is currently active; existing: 0x3b57880
I tensorflow/core/common_runtime/gpu/gpu_device.cc:885] Found device 1 with properties: 
name: Quadro K600
major: 3 minor: 0 memoryClockRate (GHz) 0.8755
pciBusID 0000:04:00.0
Total memory: 1023.81MiB
Free memory: 1006.95MiB
I tensorflow/core/common_runtime/gpu/gpu_device.cc:777] Peer access not supported between device ordinals 0 and 1
I tensorflow/core/common_runtime/gpu/gpu_device.cc:777] Peer access not supported between device ordinals 1 and 0
I tensorflow/core/common_runtime/gpu/gpu_device.cc:906] DMA: 0 1 
I tensorflow/core/common_runtime/gpu/gpu_device.cc:916] 0:   Y N 
I tensorflow/core/common_runtime/gpu/gpu_device.cc:916] 1:   N Y 
I tensorflow/core/common_runtime/gpu/gpu_device.cc:975] Creating TensorFlow device (/gpu:0) -> (device: 0, name: GeForce GTX 970, pci bus id: 0000:03:00.0)
I tensorflow/core/common_runtime/gpu/gpu_device.cc:948] Ignoring visible gpu device (device: 1, name: Quadro K600, pci bus id: 0000:04:00.0) with Cuda compute capability 3.0. The minimum required Cuda capability is 3.5.
data size 100 weight/GCD_0_0/weight
W tensorflow/core/framework/op_kernel.cc:975] Not found: Unsuccessful TensorSliceReader constructor: Failed to find any matching files for weight/GCD_0_0/weight
W tensorflow/core/framework/op_kernel.cc:975] Not found: Unsuccessful TensorSliceReader constructor: Failed to find any matching files for weight/GCD_0_0/weight
W tensorflow/core/framework/op_kernel.cc:975] Not found: Unsuccessful TensorSliceReader constructor: Failed to find any matching files for weight/GCD_0_0/weight
W tensorflow/core/framework/op_kernel.cc:975] Not found: Unsuccessful TensorSliceReader constructor: Failed to find any matching files for weight/GCD_0_0/weight
Traceback (most recent call last):
  File "eval.py", line 125, in <module>
    accuracy = eval_network(g=g,num_epochs=1,data_size=len(partial_trees),partial_trees=partial_trees,state_size=state_size,save='weight/GCD_%d_%d/weight'%(i,d),cross_validation_index=i)
  File "eval.py", line 82, in eval_network
    g['saver'].restore(sess,save)
  File "/usr/local/lib/python2.7/dist-packages/tensorflow/python/training/saver.py", line 1388, in restore
    {self.saver_def.filename_tensor_name: save_path})
  File "/usr/local/lib/python2.7/dist-packages/tensorflow/python/client/session.py", line 766, in run
    run_metadata_ptr)
  File "/usr/local/lib/python2.7/dist-packages/tensorflow/python/client/session.py", line 964, in _run
    feed_dict_string, options, run_metadata)
  File "/usr/local/lib/python2.7/dist-packages/tensorflow/python/client/session.py", line 1014, in _do_run
    target_list, options, run_metadata)
  File "/usr/local/lib/python2.7/dist-packages/tensorflow/python/client/session.py", line 1034, in _do_call
    raise type(e)(node_def, op, message)
tensorflow.python.framework.errors_impl.NotFoundError: Unsuccessful TensorSliceReader constructor: Failed to find any matching files for weight/GCD_0_0/weight
	 [[Node: save/RestoreV2 = RestoreV2[dtypes=[DT_FLOAT], _device="/job:localhost/replica:0/task:0/cpu:0"](_recv_save/Const_0, save/RestoreV2/tensor_names, save/RestoreV2/shape_and_slices)]]

Caused by op u'save/RestoreV2', defined at:
  File "eval.py", line 119, in <module>
    g = build_graph(batch_size=batch_size,state_size=state_size,learning_rate=learning_rate,node_type_size = node_type_size,vector_size=vector_size,level_max_width = level_width,parse_tree_depth=parse_tree_depth)
  File "eval.py", line 68, in build_graph
    return dict(x=x,x_1=x_1,y=y,train_trees=train_trees,saver=tf.train.Saver(),W_node=W_node,W_child=W_child,_node_rep=_node_rep,final_tree_vector=final_tree_vector,_abc_=_abc_,output=output)
  File "/usr/local/lib/python2.7/dist-packages/tensorflow/python/training/saver.py", line 1000, in __init__
    self.build()
  File "/usr/local/lib/python2.7/dist-packages/tensorflow/python/training/saver.py", line 1030, in build
    restore_sequentially=self._restore_sequentially)
  File "/usr/local/lib/python2.7/dist-packages/tensorflow/python/training/saver.py", line 624, in build
    restore_sequentially, reshape)
  File "/usr/local/lib/python2.7/dist-packages/tensorflow/python/training/saver.py", line 361, in _AddRestoreOps
    tensors = self.restore_op(filename_tensor, saveable, preferred_shard)
  File "/usr/local/lib/python2.7/dist-packages/tensorflow/python/training/saver.py", line 200, in restore_op
    [spec.tensor.dtype])[0])
  File "/usr/local/lib/python2.7/dist-packages/tensorflow/python/ops/gen_io_ops.py", line 441, in restore_v2
    dtypes=dtypes, name=name)
  File "/usr/local/lib/python2.7/dist-packages/tensorflow/python/framework/op_def_library.py", line 759, in apply_op
    op_def=op_def)
  File "/usr/local/lib/python2.7/dist-packages/tensorflow/python/framework/ops.py", line 2240, in create_op
    original_op=self._default_original_op, op_def=op_def)
  File "/usr/local/lib/python2.7/dist-packages/tensorflow/python/framework/ops.py", line 1128, in __init__
    self._traceback = _extract_stack()

NotFoundError (see above for traceback): Unsuccessful TensorSliceReader constructor: Failed to find any matching files for weight/GCD_0_0/weight
	 [[Node: save/RestoreV2 = RestoreV2[dtypes=[DT_FLOAT], _device="/job:localhost/replica:0/task:0/cpu:0"](_recv_save/Const_0, save/RestoreV2/tensor_names, save/RestoreV2/shape_and_slices)]]

